<mujoco model="MIMo">

	<body childclass="mimo" name="hip_12" pos="0 0 0">
		
		
		
		<geom name="lb_12" type="capsule" size="0.04650146243107412 0.041657560094503894 0.0" mass="1.0532577674702064" material="pants_down" pos="-0.002 0 0.004843902336570221" euler="90 0 0" />
		<site name="lowerBody_center_12" type="sphere" size=".01 .01 .01" pos="0 0 0" />
		<body name="lower_body_12" pos="0.002 0 0.07362731551586735">
			<joint name="robot:hip_lean1_12" type="hinge" pos="0 0 -.05" axis="1 0 0" range="-14 14" stiffness="3.38" damping="0.77" frictionloss=".049" armature="0.01" />
			<joint name="robot:hip_rot1_12" type="hinge" pos="0 0 -.05" axis="0 0 1" range="-18 18" stiffness="1.45" damping="0.29" frictionloss=".018" armature="0.01" />
			<joint name="robot:hip_bend1_12" type="hinge" pos="0 0 -0.05" axis="0 1 0" range="-17 30.5" stiffness="2.20" damping="0.84" frictionloss="0.040" armature="0.01" />
			<site name="torque_lb_12" type="sphere" size="0.01" pos="0 0 0" group="4" />
			<geom name="cb_12" type="capsule" size="0.051345364767644334 0.03390731635599154 0.0" mass="1.204281692864544" material="pants_up" contype="0" pos="0.005 0 -0.007750243738512352" euler="90 0 0" />
				
			<body name="upper_body_12" pos="-0.002 0 0.08815902252557802">
				<joint name="robot:hip_lean2_12" type="hinge" pos="0 0 -.05" axis="1 0 0" range="-27 27" stiffness="1.69" damping="0.38" frictionloss=".024" armature="0.01" />
				<joint name="robot:hip_rot2_12" type="hinge" pos="0 0 -.05" axis="0 0 1" range="-18 18" stiffness="1.45" damping="0.29" frictionloss=".018" armature="0.01" />
				<joint name="robot:hip_bend2_12" type="hinge" pos="0 0 -.05" axis="0 1 0" range="-17 30.5" stiffness="2.20" damping="0.84" frictionloss="0.040" armature="0.01" />
				<site name="torque_ub_12" type="sphere" size="0.01" pos="0 0 0" group="4" />
				<geom name="ub1_12" type="capsule" size="0.0503765843003303 0.03390731635599154 0.0" mass="0.9894294738959587" material="top_down" pos="0.007 0 -0.031000974954049416" euler="90 0 0" />
				<geom name="ub2_12" type="capsule" size="0.04650146243107413 0.03778243822524771 0.0" mass="0.8636822801449838" material="top_middle" pos="0.004 0 0.02906341401942133" euler="90 0 0" />
				<geom name="ub3_12" type="capsule" size="0.039719999159875806 0.04553268196376007 0.0" mass="0.6561948642811185" material="top_up" pos="0 0 0.08719024205826395" euler="90 0 0" />
					
				<body name="head_12" pos="0 0 0.13078536308739594">
					<geom name="head_12" type="sphere" size="0.07214381626595523 0.0 0.0" mass="1.6783585237712002" material="head" pos="0.01 0 0.07214381626595523" />
					<site name="vestibular_12" type="sphere" size="0.01" pos="0.01 0 0.0735" group="4" />
					<site name="torque_neck_12" type="sphere" size="0.01" pos="0 0 0" group="4" />
					<joint name="robot:head_swivel_12" type="hinge" pos="0 0 0" axis="0 0 1" range="-111 111" stiffness=".23" damping=".29" frictionloss=".018" armature="0.005" />
					<joint name="robot:head_tilt_12" type="hinge" pos="0 0 0.0123" axis="0 1 0" range="-70 81" stiffness=".45" damping=".53" frictionloss=".018" armature="0.005" />
					<joint name="robot:head_tilt_side_12" type="hinge" pos="0 0 0.0245" axis="1 0 0" range="-70 70" stiffness=".37" damping=".29" frictionloss=".018" armature="0.005" />
					<body name="left_eye_12" pos="0.0687083964437669 0.024047938755318413 0.06613183157712563">
						<site name="torque_left_eye_12" type="sphere" size="0.01" pos="0 0 0" group="4" />
						<joint name="robot:left_eye_horizontal_12" type="hinge" pos="0 0 0" axis="0 0 1" range="-45 45" stiffness=".00065" damping=".00042" frictionloss=".000054" armature=".0002" />
						<joint name="robot:left_eye_vertical_12" type="hinge" pos="0 0 0" axis="0 -1 0" range="-47 33" stiffness=".00065" damping=".00042" frictionloss=".000054" armature=".0002" />
						<joint name="robot:left_eye_torsional_12" type="hinge" pos="0 0 0" axis="-1 0 0" range="-8 8" stiffness=".00267" damping=".00042" frictionloss=".000037" armature=".0002" />
						<geom name="geom:left_eye1_12" type="sphere" material="eye_left" size="0.011042420857033964 0.0 0.0" mass="0.005934020586355805" pos="0 0 0" />
						<camera name="eye_left_12" mode="fixed" fovy="60" pos="0.01125 0 0" euler="90 -90 0" />
					</body>
					<body name="right_eye_12" pos="0.0687083964437669 -0.024047938755318413 0.06613183157712563">
						<site name="torque_right_eye_12" type="sphere" size="0.01" pos="0 0 0" group="4" />
						<joint name="robot:right_eye_horizontal_12" type="hinge" pos="0 0 0" axis="0 0 -1" range="-45 45" stiffness=".00065" damping=".00042" frictionloss=".000054" armature=".0002" />
						<joint name="robot:right_eye_vertical_12" type="hinge" pos="0 0 0" axis="0 -1 0" range="-47 33" stiffness=".00065" damping=".00042" frictionloss=".000054" armature=".0002" />
						<joint name="robot:right_eye_torsional_12" type="hinge" pos="0 0 0" axis="1 0 0" range="-8 8" stiffness=".00267" damping=".00042" frictionloss=".000037" armature=".0002" />
						<geom name="geom:right_eye1_12" type="sphere" material="eye_right" size="0.011042420857033964 0.0 0.0" mass="0.005934020586355805" pos="0 0 0" />
						<camera name="eye_right_12" mode="fixed" fovy="60" pos="0.01125 0 0" euler="90 -90 0" />
					</body>
				</body>
				
				<body name="right_upper_arm_12" pos="-0.005 -0.10216898293166662 0.09009658346020609" euler="170 0 0">
					
					<joint name="robot:right_shoulder_horizontal_12" type="hinge" pos="0 -.024 0" axis="0 1 -4" range="-28 118" stiffness=".09" damping=".05" frictionloss=".0009" armature="0.004" />
					<joint name="robot:right_shoulder_ad_ab_12" type="hinge" pos="0 0 0" axis="-1 0 0" range="-84 183" stiffness=".11" damping=".10" frictionloss=".0014" armature="0.004" />
					<joint name="robot:right_shoulder_rotation_12" type="hinge" pos="0 0 0" axis="0 0 -1" range="-99 67" stiffness=".12" damping=".07" frictionloss=".0008" armature="0.004" />
					<site name="torque_right_shoulder_12" type="sphere" size="0.01" pos="0 0 0" group="4" />
					<geom name="right_uarm1_12" type="capsule" material="top_sleeve" size="0.023727567336808537 0.0495948138557961 0.0" mass="0.24655996529911975" pos="0 0 0.0495948138557961" euler="0 0 0" />
					<body name="right_lower_arm_12" pos="0 0 0.0995212500777746" euler="0 0 0">
						<joint name="robot:right_elbow_12" type="hinge" pos="0 0 0" axis="0 -1 0" springref="-20" range="-146 5" stiffness=".13" damping=".11" frictionloss=".030" armature="0.002" />
						<site name="torque_right_elbow_12" type="sphere" size="0.01" pos="0 0 0" group="4" />
						<geom name="right_larm_12" type="capsule" size="0.022840993762014 0.03366384107863401 0.0" mass="0.17072682843845696" pos="0 0 0.03366384107863401" />
						<body name="right_hand_12" pos="0.0 -0.007 0.08087293613378901" euler="0 0 0"> 
							<joint name="robot:right_hand1_12" type="hinge" pos="0 .007 0" axis="0 0 -1" springref="-20" range="-90 90" stiffness=".22" damping=".03" frictionloss=".007" armature="0.001" />
							<joint name="robot:right_hand2_12" type="hinge" pos="0 0 0" axis="-1 0 0" range="-92 86" stiffness=".33" damping=".11" frictionloss=".007" armature="0.001" />
							<joint name="robot:right_hand3_12" type="hinge" pos="0 0 0" axis="0 1 0" range="-53 48" stiffness=".38" damping=".11" frictionloss=".007" armature="0.001" />
							<site name="torque_right_wrist_12" type="sphere" size="0.01" pos="0 0 0" group="4" />
							<geom name="geom:right_hand1_12" type="box" size="0.026683450006554785 0.009678026583555798 0.01982630240589342" mass="0.037799117675175846" pos="0.004839013291777899 0 0.01982630240589342" />
							<geom name="geom:right_hand2_12" type="cylinder" size="0.009878026583555799 0.026383450006554784 0.0" mass="0.014259008848426829" pos="0.004839013291777899 0 0.03965260481178684" euler="0 90 0" />
							<body name="right_fingers_12" pos="0 0 0.03965260481178684"> 
								<joint name="robot:right_fingers_12" type="hinge" pos="0 0 0" axis="-1 0 0" springref="-40" range="-160 8" stiffness=".017" damping=".018" frictionloss=".0023" armature="0.0001" />
								<site name="torque_right_fingers_12" type="sphere" size="0.01" pos="0 0 0" group="4" />
								<geom name="geom:right_fingers1_12" type="box" size="0.02236508184931544 0.009678026583555798 0.01973098364432662" mass="0.03161722481879204" pos="0 0 0.01973098364432662" friction="5 0.02 0.01" />
								<geom name="geom:right_fingers2_12" type="cylinder" size="0.009878026583555799 0.022565081849315438 0.0" mass="0.012173317772236299" pos="0 0 0.03946196728865324" euler="0 90 0" friction="5 0.02 0.01" />
							</body>
						</body>
					</body>
				</body>
				
				<body name="left_upper_arm_12" pos="-0.005 0.10216898293166662 0.09009658346020609" euler="-170 0 0">
					
					<joint name="robot:left_shoulder_horizontal_12" type="hinge" pos="0 .024 0" axis="0 1 4" range="-28 118" stiffness=".09" damping=".05" frictionloss=".0009" armature="0.004" />
					<joint name="robot:left_shoulder_ad_ab_12" type="hinge" pos="0 0 0" axis="1 0 0" range="-84 183" stiffness=".11" damping=".10" frictionloss=".0014" armature="0.004" />
					<joint name="robot:left_shoulder_rotation_12" type="hinge" pos="0 0 0" axis="0 0 1" range="-99 67" stiffness=".12" damping=".07" frictionloss=".0008" armature="0.004" />
					<site name="torque_left_shoulder_12" type="sphere" size="0.01" pos="0 0 0" group="4" />
					<geom name="left_uarm1_12" type="capsule" material="top_sleeve" size="0.023727567336808537 0.0495948138557961 0.0" mass="0.24655996529911975" pos="0 0 0.0495948138557961" euler="0 0 0" />
					<body name="left_lower_arm_12" pos="0 0 0.0995212500777746" euler="0 0 0">
						<joint name="robot:left_elbow_12" type="hinge" pos="0 0 0" axis="0 -1 0" springref="-20" range="-146 5" stiffness=".13" damping=".11" frictionloss=".030" armature="0.002" />
						<site name="torque_left_elbow_12" type="sphere" size="0.01" pos="0 0 0" group="4" />
						<geom name="left_larm_12" type="capsule" size="0.022840993762014 0.03366384107863401 0.0" mass="0.17072682843845696" pos="0 0 0.03366384107863401" />
						<body name="left_hand_12" pos="0 0.007 0.08087293613378901" euler="0 0 0"> 
							<joint name="robot:left_hand1_12" type="hinge" pos="0 .007 0" axis="0 0 1" springref="-20" range="-90 90" stiffness=".22" damping=".03" frictionloss=".007" armature="0.001" />
							<joint name="robot:left_hand2_12" type="hinge" pos="0 0 0" axis="1 0 0" range="-92 86" stiffness=".33" damping=".11" frictionloss=".007" armature="0.001" />
							<joint name="robot:left_hand3_12" type="hinge" pos="0 0 0" axis="0 1 0" range="-53 48" stiffness=".38" damping=".11" frictionloss=".007" armature="0.001" />
							<site name="torque_left_wrist_12" type="sphere" size="0.01" pos="0 0 0" group="4" />
							<geom name="geom:left_hand1_12" type="box" size="0.026683450006554785 0.009678026583555798 0.01982630240589342" mass="0.037799117675175846" pos="0.004839013291777899 0 0.01982630240589342" />
							<geom name="geom:left_hand2_12" type="cylinder" size="0.009878026583555799 0.026383450006554784 0.0" mass="0.014259008848426829" pos="0.004839013291777899 0 0.03965260481178684" euler="0 90 0" />
							<body name="left_fingers_12" pos="0 0 0.03965260481178684"> 
								<joint name="robot:left_fingers_12" type="hinge" pos="0 0 0" axis="1 0 0" springref="-40" range="-160 8" stiffness=".017" damping=".018" frictionloss=".0023" armature="0.0001" />
								<site name="torque_left_fingers_12" type="sphere" size="0.01" pos="0 0 0" group="4" />
								<geom name="geom:left_fingers1_12" type="box" size="0.02236508184931544 0.009678026583555798 0.01973098364432662" mass="0.03161722481879204" pos="0 0 0.01973098364432662" friction="5 0.02 0.01" />
								<geom name="geom:left_fingers2_12" type="cylinder" size="0.009878026583555799 0.022565081849315438 0.0" mass="0.012173317772236299" pos="0 0 0.03946196728865324" euler="0 90 0" friction="5 0.02 0.01" />
							</body>
						</body>
					</body>
				</body>
			</body>
		</body>
			
		<body name="right_upper_leg_12" pos="0.005 -0.05000973910959573 -0.007">
			
			<joint name="robot:right_hip1_12" type="hinge" pos="0 0 0" axis="0 1 0" springref="-10" range="-133 20" stiffness="1.72" damping="1.27" frictionloss=".08" armature=".005" />
			<joint name="robot:right_hip2_12" type="hinge" pos="0 0 0" axis="1 0 0" range="-51 17" stiffness="3.51" damping="1.99" frictionloss=".062" armature=".005" />
			<joint name="robot:right_hip3_12" type="hinge" pos="0 0 0" axis="0 0 -1" range="-32 41" stiffness="2.16" damping="0.75" frictionloss=".027" armature=".005" />
			<site name="torque_right_hip_12" type="sphere" size="0.01" pos="0 0 0" group="4" />
			<geom name="geom:right_upper_leg1_12" type="capsule" material="pants_leg" contype="2" conaffinity="3" size="0.0352075340565943 0.054767559395602 0.0" mass="0.6500150335206767" pos="0 0 -0.05652012129626127" euler="0 0 0" />
			<body name="right_lower_leg_12" pos="0 0 -0.11803238260922791">
				<joint name="robot:right_knee_12" type="hinge" pos="0 0 0" axis="0 -1 0" springref="-30" range="-145 4" stiffness="1.63" damping="0.53" frictionloss=".065" armature=".003" />
				<site name="torque_right_knee_12" type="sphere" size="0.01" pos="0 0 0" group="4" />
				<geom name="geom:right_lower_leg1_12" type="capsule" size="0.028458898129077485 0.039938895826778356 0.0" mass="0.2992845767735884" pos="0 0 -0.039938895826778356" euler="0 0 0" />
				<geom name="geom:right_lower_leg2_12" type="capsule" size="0.020628761675365637 0.02541566098067713 0.0" mass="0.10438778771396469" pos="0 0 -0.12316479355829439" euler="0 0 0" />
				<body name="right_foot_12" pos="0 0 -0.16218737652335885">
					<joint name="robot:right_foot1_12" type="hinge" pos="0 0 .015" axis="0 -1 0" springref="-10" range="-63 32" stiffness="1.29" damping="0.6" frictionloss=".019" armature=".003" />
					<joint name="robot:right_foot2_12" type="hinge" pos="0 0 .015" axis="1 0 0" range="-33 31" stiffness="0.96" damping="0.37" frictionloss=".011" armature=".0025" />
					<joint name="robot:right_foot3_12" type="hinge" pos="0 0 .015" axis="0 0 1" range="-20 30" stiffness="1.15" damping="0.38" frictionloss=".012" armature=".002" />
					<site name="torque_right_ankle_12" type="sphere" size="0.01" pos="0 0 0" group="4" />
					<geom name="geom:right_foot1_12" type="cylinder" size="0.023383200367691672 0.009271656515415385 0.0" mass="0.02658595860077561" pos="-0.014960132259274483 0 0" euler="0 0 0" />
					<geom name="geom:right_foot2_12" type="box" size="0.03272528931716293 0.02348320036769167 0.009371656515415385" mass="0.048150960442323705" pos="0.017765157057888448 0 0" euler="0 0 0" friction="2 0.02 0.01" />
					<geom name="geom:right_foot3_12" type="cylinder" size="0.009271656515415385 0.023283200367691673 0.0" mass="0.010441298872513369" pos="0.05049044637505138 0 0" euler="90 0 0" friction="2 0.02 0.01" />
					<body name="right_toes_12" pos="0.05049044637505138 0 0">
						<joint name="robot:right_toes_12" type="hinge" pos="0 0 0" axis="0 -1 0" range="-60 80" frictionloss=".005" armature=".0005" stiffness=".106" damping=".04" />
						<site name="torque_right_toes_12" type="sphere" size="0.01" pos="0 0 0" group="4" />
						<geom name="geom:right_toes1_12" type="box" size="0.006545057863432586 0.023383200367691672 0.009271656515415385" mass="0.008913976320135204" pos="0.006545057863432586 0 0" euler="0 0 0" friction="2 0.02 0.01" />
						<geom name="geom:right_toes2_12" type="cylinder" size="0.009371656515415385 0.02348320036769167 0.0" mass="0.010114408050550435" pos="0.013090115726865172 0 0" euler="90 0 0" friction="2 0.02 0.01" />
					</body>
				</body>
			</body>
		</body>
			
		<body name="left_upper_leg_12" pos="0.005 0.05000973910959573 -0.007">
			
			<joint name="robot:left_hip1_12" type="hinge" pos="0 0 0" axis="0 1 0" springref="-10" range="-133 20" stiffness="1.72" damping="1.27" frictionloss=".08" armature=".005" />
			<joint name="robot:left_hip2_12" type="hinge" pos="0 0 0" axis="-1 0 0" range="-51 17" stiffness="3.51" damping="1.99" frictionloss=".062" armature=".005" />
			<joint name="robot:left_hip3_12" type="hinge" pos="0 0 0" axis="0 0 1" range="-32 41" stiffness="2.16" damping="0.75" frictionloss=".027" armature=".005" />
			<site name="torque_left_hip_12" type="sphere" size="0.01" pos="0 0 0" group="4" />
			<geom name="geom:left_upper_leg1_12" type="capsule" material="pants_leg" contype="2" conaffinity="3" size="0.0352075340565943 0.054767559395602 0.0" mass="0.6500150335206767" pos="0 0 -0.05652012129626127" euler="0 0 0" />
			<body name="left_lower_leg_12" pos="0 0 -0.11803238260922791">
				<joint name="robot:left_knee_12" type="hinge" pos="0 0 0" axis="0 -1 0" springref="-30" range="-145 4" stiffness="1.63" damping="0.53" frictionloss=".065" armature=".003" />
				<site name="torque_left_knee_12" type="sphere" size="0.01" pos="0 0 0" group="4" />
				<geom name="geom:left_lower_leg1_12" type="capsule" size="0.028458898129077485 0.039938895826778356 0.0" mass="0.2992845767735884" pos="0 0 -0.039938895826778356" euler="0 0 0" />
				<geom name="geom:left_lower_leg2_12" type="capsule" size="0.020628761675365637 0.02541566098067713 0.0" mass="0.10438778771396469" pos="0 0 -0.12316479355829439" euler="0 0 0" />
				<body name="left_foot_12" pos="0 0 -0.16218737652335885">
					<joint name="robot:left_foot1_12" type="hinge" pos="0 0 .015" axis="0 -1 0" springref="-10" range="-63 32" stiffness="1.29" damping="0.6" frictionloss=".019" armature=".003" />
					<joint name="robot:left_foot2_12" type="hinge" pos="0 0 .015" axis="-1 0 0" range="-33 31" stiffness="0.96" damping="0.37" frictionloss=".011" armature=".0025" />
					<joint name="robot:left_foot3_12" type="hinge" pos="0 0 .015" axis="0 0 -1" range="-20 30" stiffness="1.15" damping="0.38" frictionloss=".012" armature=".002" />
					<site name="torque_left_ankle_12" type="sphere" size="0.01" pos="0 0 0" group="4" />
					<geom name="geom:left_foot1_12" type="cylinder" size="0.023383200367691672 0.009271656515415385 0.0" mass="0.02658595860077561" pos="-0.014960132259274483 0 0" euler="0 0 0" />
					<geom name="geom:left_foot2_12" type="box" size="0.03272528931716293 0.02348320036769167 0.009371656515415385" mass="0.048150960442323705" pos="0.017765157057888448 0 0" euler="0 0 0" friction="2 0.02 0.01" />
					<geom name="geom:left_foot3_12" type="cylinder" size="0.009271656515415385 0.023283200367691673 0.0" mass="0.010441298872513369" pos="0.05049044637505138 0 0" euler="90 0 0" friction="2 0.02 0.01" />
					<body name="left_toes_12" pos="0.05049044637505138 0 0">
						<joint name="robot:left_toes_12" type="hinge" pos="0 0 0" axis="0 -1 0" range="-60 80" frictionloss=".005" armature=".0005" stiffness=".106" damping=".04" />
						<site name="torque_left_toes_12" type="sphere" size="0.01" pos="0 0 0" group="4" />
						<geom name="geom:left_toes1_12" type="box" size="0.006545057863432586 0.023383200367691672 0.009271656515415385" mass="0.008913976320135204" pos="0.006545057863432586 0 0" euler="0 0 0" friction="2 0.02 0.01" />
						<geom name="geom:left_toes2_12" type="cylinder" size="0.009371656515415385 0.02348320036769167 0.0" mass="0.010114408050550435" pos="0.013090115726865172 0 0" euler="90 0 0" friction="2 0.02 0.01" />
					</body>
				</body>
			</body>
		</body>
		
	</body>

</mujoco>