<mujoco model="MIMo">

	<body childclass="mimo" name="hip_6" pos="0 0 0">
		
		
		
		<geom name="lb_6" type="capsule" size="0.0437457875214777 0.0391889346546571 0.0" mass="0.8768868439294774" material="pants_down" pos="-0.002 0 0.004556852866820595" euler="90 0 0" />
		<site name="lowerBody_center_6" type="sphere" size=".01 .01 .01" pos="0 0 0" />
		<body name="lower_body_6" pos="0.002 0 0.06926416357567301">
			<joint name="robot:hip_lean1_6" type="hinge" pos="0 0 -.05" axis="1 0 0" range="-14 14" stiffness="3.38" damping="0.77" frictionloss=".049" armature="0.01" />
			<joint name="robot:hip_rot1_6" type="hinge" pos="0 0 -.05" axis="0 0 1" range="-18 18" stiffness="1.45" damping="0.29" frictionloss=".018" armature="0.01" />
			<joint name="robot:hip_bend1_6" type="hinge" pos="0 0 -0.05" axis="0 1 0" range="-17 30.5" stiffness="2.20" damping="0.84" frictionloss="0.040" armature="0.01" />
			<site name="torque_lb_6" type="sphere" size="0.01" pos="0 0 0" group="4" />
			<geom name="cb_6" type="capsule" size="0.04830264038829829 0.031897970067744155 0.0" mass="1.0026213957049313" material="pants_up" contype="0" pos="0.005 0 -0.007290964586912949" euler="90 0 0" />
				
			<body name="upper_body_6" pos="-0.002 0 0.0829347221761348">
				<joint name="robot:hip_lean2_6" type="hinge" pos="0 0 -.05" axis="1 0 0" range="-27 27" stiffness="1.69" damping="0.38" frictionloss=".024" armature="0.01" />
				<joint name="robot:hip_rot2_6" type="hinge" pos="0 0 -.05" axis="0 0 1" range="-18 18" stiffness="1.45" damping="0.29" frictionloss=".018" armature="0.01" />
				<joint name="robot:hip_bend2_6" type="hinge" pos="0 0 -.05" axis="0 1 0" range="-17 30.5" stiffness="2.20" damping="0.84" frictionloss="0.040" armature="0.01" />
				<site name="torque_ub_6" type="sphere" size="0.01" pos="0 0 0" group="4" />
				<geom name="ub1_6" type="capsule" size="0.047391269814934175 0.031897970067744155 0.0" mass="0.8237467744855468" material="top_down" pos="0.007 0 -0.0291638583476518" euler="90 0 0" />
				<geom name="ub2_6" type="capsule" size="0.04374578752147771 0.03554345236120062 0.0" mass="0.7190562957947261" material="top_middle" pos="0.004 0 0.027341117200923568" euler="90 0 0" />
				<geom name="ub3_6" type="capsule" size="0.03736619350792887 0.042834416948113574 0.0" mass="0.5463132210496406" material="top_up" pos="0 0 0.08202335160277069" euler="90 0 0" />
					
				<body name="head_6" pos="0 0 0.12303502740415605">
					<geom name="head_6" type="sphere" size="0.06860176202344047 0.0 0.0" mass="1.4430893269165317" material="head" pos="0.01 0 0.06860176202344047" />
					<site name="vestibular_6" type="sphere" size="0.01" pos="0.01 0 0.0735" group="4" />
					<site name="torque_neck_6" type="sphere" size="0.01" pos="0 0 0" group="4" />
					<joint name="robot:head_swivel_6" type="hinge" pos="0 0 0" axis="0 0 1" range="-111 111" stiffness=".23" damping=".29" frictionloss=".018" armature="0.005" />
					<joint name="robot:head_tilt_6" type="hinge" pos="0 0 0.0123" axis="0 1 0" range="-70 81" stiffness=".45" damping=".53" frictionloss=".018" armature="0.005" />
					<joint name="robot:head_tilt_side_6" type="hinge" pos="0 0 0.0245" axis="1 0 0" range="-70 70" stiffness=".37" damping=".29" frictionloss=".018" armature="0.005" />
					<body name="left_eye_6" pos="0.0658350114508957 0.023367254007813493 0.0633849485214871">
						<site name="torque_left_eye_6" type="sphere" size="0.01" pos="0 0 0" group="4" />
						<joint name="robot:left_eye_horizontal_6" type="hinge" pos="0 0 0" axis="0 0 1" range="-45 45" stiffness=".00065" damping=".00042" frictionloss=".000054" armature=".0002" />
						<joint name="robot:left_eye_vertical_6" type="hinge" pos="0 0 0" axis="0 -1 0" range="-47 33" stiffness=".00065" damping=".00042" frictionloss=".000054" armature=".0002" />
						<joint name="robot:left_eye_torsional_6" type="hinge" pos="0 0 0" axis="-1 0 0" range="-8 8" stiffness=".00267" damping=".00042" frictionloss=".000037" armature=".0002" />
						<geom name="geom:left_eye1_6" type="sphere" material="eye_left" size="0.010500269697465378 0.0 0.0" mass="0.0051022005445127555" pos="0 0 0" />
						<camera name="eye_left_6" mode="fixed" fovy="60" pos="0.01125 0 0" euler="90 -90 0" />
					</body>
					<body name="right_eye_6" pos="0.0658350114508957 -0.023367254007813493 0.0633849485214871">
						<site name="torque_right_eye_6" type="sphere" size="0.01" pos="0 0 0" group="4" />
						<joint name="robot:right_eye_horizontal_6" type="hinge" pos="0 0 0" axis="0 0 -1" range="-45 45" stiffness=".00065" damping=".00042" frictionloss=".000054" armature=".0002" />
						<joint name="robot:right_eye_vertical_6" type="hinge" pos="0 0 0" axis="0 -1 0" range="-47 33" stiffness=".00065" damping=".00042" frictionloss=".000054" armature=".0002" />
						<joint name="robot:right_eye_torsional_6" type="hinge" pos="0 0 0" axis="1 0 0" range="-8 8" stiffness=".00267" damping=".00042" frictionloss=".000037" armature=".0002" />
						<geom name="geom:right_eye1_6" type="sphere" material="eye_right" size="0.010500269697465378 0.0 0.0" mass="0.0051022005445127555" pos="0 0 0" />
						<camera name="eye_right_6" mode="fixed" fovy="60" pos="0.01125 0 0" euler="90 -90 0" />
					</body>
				</body>
				
				<body name="right_upper_arm_6" pos="-0.005 -0.09626664352952974 0.08475746332286305" euler="170 0 0">
					
					<joint name="robot:right_shoulder_horizontal_6" type="hinge" pos="0 -.024 0" axis="0 1 -4" range="-28 118" stiffness=".09" damping=".05" frictionloss=".0009" armature="0.004" />
					<joint name="robot:right_shoulder_ad_ab_6" type="hinge" pos="0 0 0" axis="-1 0 0" range="-84 183" stiffness=".11" damping=".10" frictionloss=".0014" armature="0.004" />
					<joint name="robot:right_shoulder_rotation_6" type="hinge" pos="0 0 0" axis="0 0 -1" range="-99 67" stiffness=".12" damping=".07" frictionloss=".0008" armature="0.004" />
					<site name="torque_right_shoulder_6" type="sphere" size="0.01" pos="0 0 0" group="4" />
					<geom name="right_uarm1_6" type="capsule" material="top_sleeve" size="0.022483809308789283 0.04275018942756355 0.0" mass="0.19541721010750204" pos="0 0 0.04275018942756355" euler="0 0 0" />
					<body name="right_lower_arm_6" pos="0 0 0.08579741476815153" euler="0 0 0">
						<joint name="robot:right_elbow_6" type="hinge" pos="0 0 0" axis="0 -1 0" springref="-20" range="-146 5" stiffness=".13" damping=".11" frictionloss=".030" armature="0.002" />
						<site name="torque_right_elbow_6" type="sphere" size="0.01" pos="0 0 0" group="4" />
						<geom name="right_larm_6" type="capsule" size="0.021708349149845773 0.028366406988047408 0.0" mass="0.13512341662843388" pos="0 0 0.028366406988047408" />
						<body name="right_hand_6" pos="0.0 -0.007 0.07035444527790546" euler="0 0 0"> 
							<joint name="robot:right_hand1_6" type="hinge" pos="0 .007 0" axis="0 0 -1" springref="-20" range="-90 90" stiffness=".22" damping=".03" frictionloss=".007" armature="0.001" />
							<joint name="robot:right_hand2_6" type="hinge" pos="0 0 0" axis="-1 0 0" range="-92 86" stiffness=".33" damping=".11" frictionloss=".007" armature="0.001" />
							<joint name="robot:right_hand3_6" type="hinge" pos="0 0 0" axis="0 1 0" range="-53 48" stiffness=".38" damping=".11" frictionloss=".007" armature="0.001" />
							<site name="torque_right_wrist_6" type="sphere" size="0.01" pos="0 0 0" group="4" />
							<geom name="geom:right_hand1_6" type="box" size="0.024860296384478134 0.00890415939959421 0.01789730942328192" mass="0.029248131037344617" pos="0.004452079699797105 0 0.01789730942328192" />
							<geom name="geom:right_hand2_6" type="cylinder" size="0.00910415939959421 0.024560296384478132 0.0" mass="0.011275366870784434" pos="0.004452079699797105 0 0.03579461884656384" euler="0 90 0" />
							<body name="right_fingers_6" pos="0 0 0.03579461884656384"> 
								<joint name="robot:right_fingers_6" type="hinge" pos="0 0 0" axis="-1 0 0" springref="-40" range="-160 8" stiffness=".017" damping=".018" frictionloss=".0023" armature="0.0001" />
								<site name="torque_right_fingers_6" type="sphere" size="0.01" pos="0 0 0" group="4" />
								<geom name="geom:right_fingers1_6" type="box" size="0.02092308852857157 0.00890415939959421 0.017811264666439213" mass="0.024565815393841256" pos="0 0 0.017811264666439213" friction="5 0.02 0.01" />
								<geom name="geom:right_fingers2_6" type="cylinder" size="0.00910415939959421 0.02112308852857157 0.0" mass="0.009679853615988795" pos="0 0 0.035622529332878426" euler="0 90 0" friction="5 0.02 0.01" />
							</body>
						</body>
					</body>
				</body>
				
				<body name="left_upper_arm_6" pos="-0.005 0.09626664352952974 0.08475746332286305" euler="-170 0 0">
					
					<joint name="robot:left_shoulder_horizontal_6" type="hinge" pos="0 .024 0" axis="0 1 4" range="-28 118" stiffness=".09" damping=".05" frictionloss=".0009" armature="0.004" />
					<joint name="robot:left_shoulder_ad_ab_6" type="hinge" pos="0 0 0" axis="1 0 0" range="-84 183" stiffness=".11" damping=".10" frictionloss=".0014" armature="0.004" />
					<joint name="robot:left_shoulder_rotation_6" type="hinge" pos="0 0 0" axis="0 0 1" range="-99 67" stiffness=".12" damping=".07" frictionloss=".0008" armature="0.004" />
					<site name="torque_left_shoulder_6" type="sphere" size="0.01" pos="0 0 0" group="4" />
					<geom name="left_uarm1_6" type="capsule" material="top_sleeve" size="0.022483809308789283 0.04275018942756355 0.0" mass="0.19541721010750204" pos="0 0 0.04275018942756355" euler="0 0 0" />
					<body name="left_lower_arm_6" pos="0 0 0.08579741476815153" euler="0 0 0">
						<joint name="robot:left_elbow_6" type="hinge" pos="0 0 0" axis="0 -1 0" springref="-20" range="-146 5" stiffness=".13" damping=".11" frictionloss=".030" armature="0.002" />
						<site name="torque_left_elbow_6" type="sphere" size="0.01" pos="0 0 0" group="4" />
						<geom name="left_larm_6" type="capsule" size="0.021708349149845773 0.028366406988047408 0.0" mass="0.13512341662843388" pos="0 0 0.028366406988047408" />
						<body name="left_hand_6" pos="0 0.007 0.07035444527790546" euler="0 0 0"> 
							<joint name="robot:left_hand1_6" type="hinge" pos="0 .007 0" axis="0 0 1" springref="-20" range="-90 90" stiffness=".22" damping=".03" frictionloss=".007" armature="0.001" />
							<joint name="robot:left_hand2_6" type="hinge" pos="0 0 0" axis="1 0 0" range="-92 86" stiffness=".33" damping=".11" frictionloss=".007" armature="0.001" />
							<joint name="robot:left_hand3_6" type="hinge" pos="0 0 0" axis="0 1 0" range="-53 48" stiffness=".38" damping=".11" frictionloss=".007" armature="0.001" />
							<site name="torque_left_wrist_6" type="sphere" size="0.01" pos="0 0 0" group="4" />
							<geom name="geom:left_hand1_6" type="box" size="0.024860296384478134 0.00890415939959421 0.01789730942328192" mass="0.029248131037344617" pos="0.004452079699797105 0 0.01789730942328192" />
							<geom name="geom:left_hand2_6" type="cylinder" size="0.00910415939959421 0.024560296384478132 0.0" mass="0.011275366870784434" pos="0.004452079699797105 0 0.03579461884656384" euler="0 90 0" />
							<body name="left_fingers_6" pos="0 0 0.03579461884656384"> 
								<joint name="robot:left_fingers_6" type="hinge" pos="0 0 0" axis="1 0 0" springref="-40" range="-160 8" stiffness=".017" damping=".018" frictionloss=".0023" armature="0.0001" />
								<site name="torque_left_fingers_6" type="sphere" size="0.01" pos="0 0 0" group="4" />
								<geom name="geom:left_fingers1_6" type="box" size="0.02092308852857157 0.00890415939959421 0.017811264666439213" mass="0.024565815393841256" pos="0 0 0.017811264666439213" friction="5 0.02 0.01" />
								<geom name="geom:left_fingers2_6" type="cylinder" size="0.00910415939959421 0.02112308852857157 0.0" mass="0.009679853615988795" pos="0 0 0.035622529332878426" euler="0 90 0" friction="5 0.02 0.01" />
							</body>
						</body>
					</body>
				</body>
			</body>
		</body>
			
		<body name="right_upper_leg_6" pos="0.005 -0.0485016618197916 -0.007">
			
			<joint name="robot:right_hip1_6" type="hinge" pos="0 0 0" axis="0 1 0" springref="-10" range="-133 20" stiffness="1.72" damping="1.27" frictionloss=".08" armature=".005" />
			<joint name="robot:right_hip2_6" type="hinge" pos="0 0 0" axis="1 0 0" range="-51 17" stiffness="3.51" damping="1.99" frictionloss=".062" armature=".005" />
			<joint name="robot:right_hip3_6" type="hinge" pos="0 0 0" axis="0 0 -1" range="-32 41" stiffness="2.16" damping="0.75" frictionloss=".027" armature=".005" />
			<site name="torque_right_hip_6" type="sphere" size="0.01" pos="0 0 0" group="4" />
			<geom name="geom:right_upper_leg1_6" type="capsule" material="pants_leg" contype="2" conaffinity="3" size="0.03158002142576723 0.046565148492024165 0.0" mass="0.45197858824421544" pos="0 0 -0.04805523324376894" euler="0 0 0" />
			<body name="right_lower_leg_6" pos="0 0 -0.09989369573350015">
				<joint name="robot:right_knee_6" type="hinge" pos="0 0 0" axis="0 -1 0" springref="-30" range="-145 4" stiffness="1.63" damping="0.53" frictionloss=".065" armature=".003" />
				<site name="torque_right_knee_6" type="sphere" size="0.01" pos="0 0 0" group="4" />
				<geom name="geom:right_lower_leg1_6" type="capsule" size="0.02629652927977467 0.034241102617296834 0.0" mass="0.22456442913265115" pos="0 0 -0.034241102617296834" euler="0 0 0" />
				<geom name="geom:right_lower_leg2_6" type="capsule" size="0.01921740152202623 0.021789792574643436 0.0" mass="0.08003003898046787" pos="0 0 -0.10709182124371742" euler="0 0 0" />
				<body name="right_foot_6" pos="0 0 -0.14053891867078383">
					<joint name="robot:right_foot1_6" type="hinge" pos="0 0 .015" axis="0 -1 0" springref="-10" range="-63 32" stiffness="1.29" damping="0.6" frictionloss=".019" armature=".003" />
					<joint name="robot:right_foot2_6" type="hinge" pos="0 0 .015" axis="1 0 0" range="-33 31" stiffness="0.96" damping="0.37" frictionloss=".011" armature=".0025" />
					<joint name="robot:right_foot3_6" type="hinge" pos="0 0 .015" axis="0 0 1" range="-20 30" stiffness="1.15" damping="0.38" frictionloss=".012" armature=".002" />
					<site name="torque_right_ankle_6" type="sphere" size="0.01" pos="0 0 0" group="4" />
					<geom name="geom:right_foot1_6" type="cylinder" size="0.02084967224784996 0.008191317140173246 0.0" mass="0.01867408336586688" pos="-0.013125921800707117 0 0" euler="0 0 0" />
					<geom name="geom:right_foot2_6" type="box" size="0.02871295393904682 0.02094967224784996 0.008291317140173246" mass="0.03334467181307827" pos="0.015587032138339701 0 0" euler="0 0 0" friction="2 0.02 0.01" />
					<geom name="geom:right_foot3_6" type="cylinder" size="0.008191317140173246 0.02074967224784996 0.0" mass="0.007262997690521047" pos="0.04429998607738652 0 0" euler="90 0 0" friction="2 0.02 0.01" />
					<body name="right_toes_6" pos="0.04429998607738652 0 0">
						<joint name="robot:right_toes_6" type="hinge" pos="0 0 0" axis="0 -1 0" range="-60 80" frictionloss=".005" armature=".0005" stiffness=".106" damping=".04" />
						<site name="torque_right_toes_6" type="sphere" size="0.01" pos="0 0 0" group="4" />
						<geom name="geom:right_toes1_6" type="box" size="0.005742590787809363 0.02084967224784996 0.008191317140173246" mass="0.006161089865484512" pos="0.005742590787809363 0 0" euler="0 0 0" friction="2 0.02 0.01" />
						<geom name="geom:right_toes2_6" type="cylinder" size="0.008291317140173246 0.02094967224784996 0.0" mass="0.007062764877031398" pos="0.011485181575618727 0 0" euler="90 0 0" friction="2 0.02 0.01" />
					</body>
				</body>
			</body>
		</body>
			
		<body name="left_upper_leg_6" pos="0.005 0.0485016618197916 -0.007">
			
			<joint name="robot:left_hip1_6" type="hinge" pos="0 0 0" axis="0 1 0" springref="-10" range="-133 20" stiffness="1.72" damping="1.27" frictionloss=".08" armature=".005" />
			<joint name="robot:left_hip2_6" type="hinge" pos="0 0 0" axis="-1 0 0" range="-51 17" stiffness="3.51" damping="1.99" frictionloss=".062" armature=".005" />
			<joint name="robot:left_hip3_6" type="hinge" pos="0 0 0" axis="0 0 1" range="-32 41" stiffness="2.16" damping="0.75" frictionloss=".027" armature=".005" />
			<site name="torque_left_hip_6" type="sphere" size="0.01" pos="0 0 0" group="4" />
			<geom name="geom:left_upper_leg1_6" type="capsule" material="pants_leg" contype="2" conaffinity="3" size="0.03158002142576723 0.046565148492024165 0.0" mass="0.45197858824421544" pos="0 0 -0.04805523324376894" euler="0 0 0" />
			<body name="left_lower_leg_6" pos="0 0 -0.09989369573350015">
				<joint name="robot:left_knee_6" type="hinge" pos="0 0 0" axis="0 -1 0" springref="-30" range="-145 4" stiffness="1.63" damping="0.53" frictionloss=".065" armature=".003" />
				<site name="torque_left_knee_6" type="sphere" size="0.01" pos="0 0 0" group="4" />
				<geom name="geom:left_lower_leg1_6" type="capsule" size="0.02629652927977467 0.034241102617296834 0.0" mass="0.22456442913265115" pos="0 0 -0.034241102617296834" euler="0 0 0" />
				<geom name="geom:left_lower_leg2_6" type="capsule" size="0.01921740152202623 0.021789792574643436 0.0" mass="0.08003003898046787" pos="0 0 -0.10709182124371742" euler="0 0 0" />
				<body name="left_foot_6" pos="0 0 -0.14053891867078383">
					<joint name="robot:left_foot1_6" type="hinge" pos="0 0 .015" axis="0 -1 0" springref="-10" range="-63 32" stiffness="1.29" damping="0.6" frictionloss=".019" armature=".003" />
					<joint name="robot:left_foot2_6" type="hinge" pos="0 0 .015" axis="-1 0 0" range="-33 31" stiffness="0.96" damping="0.37" frictionloss=".011" armature=".0025" />
					<joint name="robot:left_foot3_6" type="hinge" pos="0 0 .015" axis="0 0 -1" range="-20 30" stiffness="1.15" damping="0.38" frictionloss=".012" armature=".002" />
					<site name="torque_left_ankle_6" type="sphere" size="0.01" pos="0 0 0" group="4" />
					<geom name="geom:left_foot1_6" type="cylinder" size="0.02084967224784996 0.008191317140173246 0.0" mass="0.01867408336586688" pos="-0.013125921800707117 0 0" euler="0 0 0" />
					<geom name="geom:left_foot2_6" type="box" size="0.02871295393904682 0.02094967224784996 0.008291317140173246" mass="0.03334467181307827" pos="0.015587032138339701 0 0" euler="0 0 0" friction="2 0.02 0.01" />
					<geom name="geom:left_foot3_6" type="cylinder" size="0.008191317140173246 0.02074967224784996 0.0" mass="0.007262997690521047" pos="0.04429998607738652 0 0" euler="90 0 0" friction="2 0.02 0.01" />
					<body name="left_toes_6" pos="0.04429998607738652 0 0">
						<joint name="robot:left_toes_6" type="hinge" pos="0 0 0" axis="0 -1 0" range="-60 80" frictionloss=".005" armature=".0005" stiffness=".106" damping=".04" />
						<site name="torque_left_toes_6" type="sphere" size="0.01" pos="0 0 0" group="4" />
						<geom name="geom:left_toes1_6" type="box" size="0.005742590787809363 0.02084967224784996 0.008191317140173246" mass="0.006161089865484512" pos="0.005742590787809363 0 0" euler="0 0 0" friction="2 0.02 0.01" />
						<geom name="geom:left_toes2_6" type="cylinder" size="0.008291317140173246 0.02094967224784996 0.0" mass="0.007062764877031398" pos="0.011485181575618727 0 0" euler="90 0 0" friction="2 0.02 0.01" />
					</body>
				</body>
			</body>
		</body>
		
	</body>

</mujoco>